<?xml version="1.0"?>
<robot xmlns:xacro="http://www.ros.org/wiki/xacro" name="firebot">

    <xacro:include filename="inertial_macros.xacro"/>

    <material name="white">
        <color rgba="1 1 1 1" />
    </material>

    <material name="orange">
        <color rgba="1 0.3 0.1 1"/>
    </material>

    <material name="blue">
        <color rgba="0.2 0.2 1 1"/>
    </material>

    <material name="black">
        <color rgba="0 0 0 1"/>
    </material>

    <material name="red">
        <color rgba="0.8 0.1 0.1 1"/>
    </material>

    <!-- BASE LINK -->

    <link name="base_link">

    </link>

    <!-- BASE_FOOTPRINT LINK -->

    <joint name="base_footprint_joint" type="fixed">
        <parent link="base_link"/>
        <child link="base_footprint"/>
        <origin xyz="0 0 -0.05" rpy="0 0 0"/>
    </joint>

    <link name="base_footprint">
    </link>

    <!-- CHASSIS LINK -->

    <joint name="chassis_joint" type="fixed">
        <parent link="base_link"/>
        <child link="chassis"/>
        <origin xyz="-0.1 0 0"/>
    </joint>

    <link name="chassis">
        <visual>
            <origin xyz="0.15 0 0.075"/>
            <geometry>
                <box size="0.3 0.3 0.15"/>
            </geometry>
            <material name="white"/>
        </visual>
        <collision>
            <origin xyz="0.15 0 0.075"/>
            <geometry>
                <box size="0.3 0.3 0.15"/>
            </geometry>
        </collision>
        <xacro:inertial_box mass="0.5" x="0.3" y="0.3" z="0.15">
            <origin xyz="0.15 0 0.075" rpy="0 0 0"/>
        </xacro:inertial_box>
    </link>

    <gazebo reference="chassis">
        <material>Gazebo/White</material>
    </gazebo>

    <!-- WATER TANK LINK -->

    <joint name="water_tank_joint" type="fixed">
        <parent link="chassis"/>
        <child link="water_tank"/>
        <origin xyz="0.15 0 0.175" rpy="0 0 0"/>
    </joint>

    <link name="water_tank">
        <visual>
            <origin xyz="0 0 0.075"/>
            <geometry>
                <cylinder radius="0.1" length="0.15"/>
            </geometry>
            <material name="blue"/>
        </visual>
        <collision>
            <origin xyz="0 0 0.075"/>
            <geometry>
                <cylinder radius="0.1" length="0.15"/>
            </geometry>
        </collision>
        <xacro:inertial_cylinder mass="2.0" length="0.15" radius="0.1">
            <origin xyz="0 0 0.075" rpy="0 0 0"/>
        </xacro:inertial_cylinder>
    </link>

    <gazebo reference="water_tank">
        <material>Gazebo/Blue</material>
    </gazebo>

    <!-- WATER PUMP LINK -->

    <joint name="water_pump_joint" type="fixed">
        <parent link="water_tank"/>
        <child link="water_pump"/>
        <origin xyz="0 0 0.15" rpy="0 0 0"/>
    </joint>

    <link name="water_pump">
        <visual>
            <origin xyz="0 0 0.025"/>
            <geometry>
                <box size="0.08 0.08 0.05"/>
            </geometry>
            <material name="black"/>
        </visual>
        <collision>
            <origin xyz="0 0 0.025"/>
            <geometry>
                <box size="0.08 0.08 0.05"/>
            </geometry>
        </collision>
        <xacro:inertial_box mass="0.3" x="0.08" y="0.08" z="0.05">
            <origin xyz="0 0 0.025" rpy="0 0 0"/>
        </xacro:inertial_box>
    </link>

    <gazebo reference="water_pump">
        <material>Gazebo/Black</material>
    </gazebo>

    <!-- FRONT LEFT WHEEL LINK -->

    <joint name="front_left_wheel_joint" type="continuous">
        <parent link="base_link"/>
        <child link="front_left_wheel"/>
        <origin xyz="0.1 0.175 0" rpy="-${pi/2} 0 0" />
        <axis xyz="0 0 1"/>
    </joint>

    <link name="front_left_wheel">
        <visual>
            <geometry>
                <cylinder radius="0.05" length="0.04"/>
            </geometry>
            <material name="blue"/>
        </visual>
        <collision>
            <geometry>
                <cylinder radius="0.05" length="0.04"/>
            </geometry>
        </collision>
        <xacro:inertial_cylinder mass="0.1" length="0.04" radius="0.05">
            <origin xyz="0 0 0" rpy="0 0 0"/>
        </xacro:inertial_cylinder>
    </link>

    <gazebo reference="front_left_wheel">
        <material>Gazebo/Blue</material>
    </gazebo>

    <!-- FRONT RIGHT WHEEL LINK -->

    <joint name="front_right_wheel_joint" type="continuous">
        <parent link="base_link"/>
        <child link="front_right_wheel"/>
        <origin xyz="0.1 -0.175 0" rpy="${pi/2} 0 0" />
        <axis xyz="0 0 -1"/>
    </joint>

    <link name="front_right_wheel">
        <visual>
            <geometry>
                <cylinder radius="0.05" length="0.04"/>
            </geometry>
            <material name="blue"/>
        </visual>
        <collision>
            <geometry>
                <cylinder radius="0.05" length="0.04"/>
            </geometry>
        </collision>
        <xacro:inertial_cylinder mass="0.1" length="0.04" radius="0.05">
            <origin xyz="0 0 0" rpy="0 0 0"/>
        </xacro:inertial_cylinder>
    </link>

    <gazebo reference="front_right_wheel">
        <material>Gazebo/Blue</material>
    </gazebo>

    <!-- REAR LEFT WHEEL LINK -->

    <joint name="rear_left_wheel_joint" type="continuous">
        <parent link="base_link"/>
        <child link="rear_left_wheel"/>
        <origin xyz="-0.1 0.175 0" rpy="-${pi/2} 0 0" />
        <axis xyz="0 0 1"/>
    </joint>

    <link name="rear_left_wheel">
        <visual>
            <geometry>
                <cylinder radius="0.05" length="0.04"/>
            </geometry>
            <material name="blue"/>
        </visual>
        <collision>
            <geometry>
                <cylinder radius="0.05" length="0.04"/>
            </geometry>
        </collision>
        <xacro:inertial_cylinder mass="0.1" length="0.04" radius="0.05">
            <origin xyz="0 0 0" rpy="0 0 0"/>
        </xacro:inertial_cylinder>
    </link>

    <gazebo reference="rear_left_wheel">
        <material>Gazebo/Blue</material>
    </gazebo>

    <!-- REAR RIGHT WHEEL LINK -->

    <joint name="rear_right_wheel_joint" type="continuous">
        <parent link="base_link"/>
        <child link="rear_right_wheel"/>
        <origin xyz="-0.1 -0.175 0" rpy="${pi/2} 0 0" />
        <axis xyz="0 0 -1"/>
    </joint>

    <link name="rear_right_wheel">
        <visual>
            <geometry>
                <cylinder radius="0.05" length="0.04"/>
            </geometry>
            <material name="blue"/>
        </visual>
        <collision>
            <geometry>
                <cylinder radius="0.05" length="0.04"/>
            </geometry>
        </collision>
        <xacro:inertial_cylinder mass="0.1" length="0.04" radius="0.05">
            <origin xyz="0 0 0" rpy="0 0 0"/>
        </xacro:inertial_cylinder>
    </link>

    <gazebo reference="rear_right_wheel">
        <material>Gazebo/Blue</material>
    </gazebo>

    <!-- CAMERA LINK -->

    <joint name="camera_joint" type="fixed">
        <parent link="chassis"/>
        <child link="camera_link"/>
        <origin xyz="0.305 0 0.08" rpy="0 0 0"/>
    </joint>

    <link name="camera_link">
        <visual>
            <geometry>
                <box size="0.010 0.03 0.03"/>
            </geometry>
            <material name="red"/>
        </visual>
        <collision>
            <geometry>
                <box size="0.010 0.03 0.03"/>
            </geometry>
        </collision>
        <xacro:inertial_box mass="0.1" x="0.010" y="0.03" z="0.03">
            <origin xyz="0 0 0" rpy="0 0 0"/>
        </xacro:inertial_box>
    </link>

    <gazebo reference="camera_link">
        <material>Gazebo/Red</material>
        <sensor name="camera" type="camera">
            <pose> 0 0 0 0 0 0 </pose>
            <visualize>true</visualize>
            <update_rate>10</update_rate>
            <camera>
                <horizontal_fov>1.089</horizontal_fov>
                <image>
                    <format>R8G8B8</format>
                    <width>640</width>
                    <height>480</height>
                </image>
                <clip>
                    <near>0.05</near>
                    <far>8.0</far>
                </clip>
            </camera>
            <plugin name="camera_controller" filename="libgazebo_ros_camera.so">
                <ros>
                    <namespace>/</namespace>
                    <remapping>image_raw:=camera/image_raw</remapping>
                    <remapping>camera_info:=camera/camera_info</remapping>
                </ros>
                <camera_name>camera</camera_name>
                <frame_name>camera_link_optical</frame_name>
            </plugin>
        </sensor>
    </gazebo>

    <joint name="camera_optical_joint" type="fixed">
        <parent link="camera_link"/>
        <child link="camera_link_optical"/>
        <origin xyz="0 0 0" rpy="-${pi/2} 0 -${pi/2}"/>
    </joint>

    <link name="camera_link_optical"></link>

    <!-- GAZEBO CONTROL FOR 4-WHEEL SKID STEER (FOXY COMPATIBLE) -->
    <gazebo>
        <plugin name="skid_steer_drive_controller" filename="libgazebo_ros_skid_steer_drive.so">
            <update_rate>50</update_rate>
            <num_wheel_pairs>2</num_wheel_pairs>
            <left_front_joint>front_left_wheel_joint</left_front_joint>
            <right_front_joint>front_right_wheel_joint</right_front_joint>
            <left_rear_joint>rear_left_wheel_joint</left_rear_joint>
            <right_rear_joint>rear_right_wheel_joint</right_rear_right_joint>
            <wheel_separation>0.35</wheel_separation>
            <wheel_diameter>0.1</wheel_diameter>
            <robot_base_frame>base_link</robot_base_frame>
            <topic_name>cmd_vel</topic_name>
            <broadcast_tf>true</broadcast_tf>
            <ros>
                <namespace>/</namespace>
                <remapping>cmd_vel:=cmd_vel</remapping>
                <remapping>odom:=odom</remapping>
            </ros>
        </plugin>
    </gazebo>

</robot>